[2022-03-18 21:04:08,147] {taskinstance.py:876} INFO - Dependencies all met for <TaskInstance: xcom_dag.task_4 2022-03-17T00:00:00+00:00 [queued]>
[2022-03-18 21:04:08,192] {taskinstance.py:876} INFO - Dependencies all met for <TaskInstance: xcom_dag.task_4 2022-03-17T00:00:00+00:00 [queued]>
[2022-03-18 21:04:08,192] {taskinstance.py:1067} INFO - 
--------------------------------------------------------------------------------
[2022-03-18 21:04:08,193] {taskinstance.py:1068} INFO - Starting attempt 3 of 3
[2022-03-18 21:04:08,194] {taskinstance.py:1069} INFO - 
--------------------------------------------------------------------------------
[2022-03-18 21:04:08,214] {taskinstance.py:1087} INFO - Executing <Task(PythonOperator): task_4> on 2022-03-17T00:00:00+00:00
[2022-03-18 21:04:08,224] {standard_task_runner.py:52} INFO - Started process 7190 to run task
[2022-03-18 21:04:08,230] {standard_task_runner.py:76} INFO - Running: ['airflow', 'tasks', 'run', 'xcom_dag', 'task_4', '2022-03-17T00:00:00+00:00', '--job-id', '45', '--pool', 'default_pool', '--raw', '--subdir', 'DAGS_FOLDER/xcom_dag.py', '--cfg-path', '/tmp/tmpo1rvc2bd', '--error-file', '/tmp/tmptq5ketwy']
[2022-03-18 21:04:08,233] {standard_task_runner.py:77} INFO - Job 45: Subtask task_4
[2022-03-18 21:04:08,323] {logging_mixin.py:104} INFO - Running <TaskInstance: xcom_dag.task_4 2022-03-17T00:00:00+00:00 [running]> on host pc
[2022-03-18 21:04:08,454] {taskinstance.py:1282} INFO - Exporting the following env vars:
AIRFLOW_CTX_DAG_OWNER=airflow
AIRFLOW_CTX_DAG_ID=xcom_dag
AIRFLOW_CTX_TASK_ID=task_4
AIRFLOW_CTX_EXECUTION_DATE=2022-03-17T00:00:00+00:00
AIRFLOW_CTX_DAG_RUN_ID=scheduled__2022-03-17T00:00:00+00:00
[2022-03-18 21:04:08,455] {taskinstance.py:1481} ERROR - Task failed with exception
Traceback (most recent call last):
  File "/home/anupam/venv/lib/python3.6/site-packages/airflow/models/taskinstance.py", line 1137, in _run_raw_task
    self._prepare_and_execute_task_with_callbacks(context, task)
  File "/home/anupam/venv/lib/python3.6/site-packages/airflow/models/taskinstance.py", line 1311, in _prepare_and_execute_task_with_callbacks
    result = self._execute_task(context, task_copy)
  File "/home/anupam/venv/lib/python3.6/site-packages/airflow/models/taskinstance.py", line 1341, in _execute_task
    result = task_copy.execute(context=context)
  File "/home/anupam/venv/lib/python3.6/site-packages/airflow/operators/python.py", line 150, in execute
    return_value = self.execute_callable()
  File "/home/anupam/venv/lib/python3.6/site-packages/airflow/operators/python.py", line 161, in execute_callable
    return self.python_callable(*self.op_args, **self.op_kwargs)
  File "/home/anupam/airflow/dags/xcom_dag.py", line 20, in _choose_best_model
    val = ti.xcom_pull('accuracy',task_ids=['processing_tasks.training_model_a','processing_tasks.training_model_b','processing_tasks.training_model_c'])
  File "/home/anupam/venv/lib/python3.6/site-packages/airflow/utils/session.py", line 70, in wrapper
    return func(*args, session=session, **kwargs)
TypeError: xcom_pull() got multiple values for argument 'task_ids'
[2022-03-18 21:04:08,458] {taskinstance.py:1531} INFO - Marking task as FAILED. dag_id=xcom_dag, task_id=task_4, execution_date=20220317T000000, start_date=20220318T153408, end_date=20220318T153408
[2022-03-18 21:04:08,521] {local_task_job.py:151} INFO - Task exited with return code 1
