[2022-03-18 21:30:49,607] {taskinstance.py:876} INFO - Dependencies all met for <TaskInstance: xcom_dag.is_accurate 2022-03-17T00:00:00+00:00 [queued]>
[2022-03-18 21:30:49,647] {taskinstance.py:876} INFO - Dependencies all met for <TaskInstance: xcom_dag.is_accurate 2022-03-17T00:00:00+00:00 [queued]>
[2022-03-18 21:30:49,647] {taskinstance.py:1067} INFO - 
--------------------------------------------------------------------------------
[2022-03-18 21:30:49,647] {taskinstance.py:1068} INFO - Starting attempt 2 of 2
[2022-03-18 21:30:49,649] {taskinstance.py:1069} INFO - 
--------------------------------------------------------------------------------
[2022-03-18 21:30:49,671] {taskinstance.py:1087} INFO - Executing <Task(BranchPythonOperator): is_accurate> on 2022-03-17T00:00:00+00:00
[2022-03-18 21:30:49,681] {standard_task_runner.py:52} INFO - Started process 10328 to run task
[2022-03-18 21:30:49,690] {standard_task_runner.py:76} INFO - Running: ['airflow', 'tasks', 'run', 'xcom_dag', 'is_accurate', '2022-03-17T00:00:00+00:00', '--job-id', '62', '--pool', 'default_pool', '--raw', '--subdir', 'DAGS_FOLDER/xcom_dag.py', '--cfg-path', '/tmp/tmpx_qe7uop', '--error-file', '/tmp/tmp2tiiqhg4']
[2022-03-18 21:30:49,694] {standard_task_runner.py:77} INFO - Job 62: Subtask is_accurate
[2022-03-18 21:30:49,769] {logging_mixin.py:104} INFO - Running <TaskInstance: xcom_dag.is_accurate 2022-03-17T00:00:00+00:00 [running]> on host pc
[2022-03-18 21:30:49,896] {taskinstance.py:1282} INFO - Exporting the following env vars:
AIRFLOW_CTX_DAG_OWNER=airflow
AIRFLOW_CTX_DAG_ID=xcom_dag
AIRFLOW_CTX_TASK_ID=is_accurate
AIRFLOW_CTX_EXECUTION_DATE=2022-03-17T00:00:00+00:00
AIRFLOW_CTX_DAG_RUN_ID=scheduled__2022-03-17T00:00:00+00:00
[2022-03-18 21:30:49,912] {taskinstance.py:1481} ERROR - Task failed with exception
Traceback (most recent call last):
  File "/home/anupam/venv/lib/python3.6/site-packages/airflow/models/taskinstance.py", line 1137, in _run_raw_task
    self._prepare_and_execute_task_with_callbacks(context, task)
  File "/home/anupam/venv/lib/python3.6/site-packages/airflow/models/taskinstance.py", line 1311, in _prepare_and_execute_task_with_callbacks
    result = self._execute_task(context, task_copy)
  File "/home/anupam/venv/lib/python3.6/site-packages/airflow/models/taskinstance.py", line 1341, in _execute_task
    result = task_copy.execute(context=context)
  File "/home/anupam/venv/lib/python3.6/site-packages/airflow/operators/python.py", line 179, in execute
    branch = super().execute(context)
  File "/home/anupam/venv/lib/python3.6/site-packages/airflow/operators/python.py", line 150, in execute
    return_value = self.execute_callable()
  File "/home/anupam/venv/lib/python3.6/site-packages/airflow/operators/python.py", line 161, in execute_callable
    return self.python_callable(*self.op_args, **self.op_kwargs)
  File "/home/anupam/airflow/dags/xcom_dag.py", line 33, in _is_accurate
    if val >5.0:
TypeError: '>' not supported between instances of 'list' and 'float'
[2022-03-18 21:30:49,914] {taskinstance.py:1531} INFO - Marking task as FAILED. dag_id=xcom_dag, task_id=is_accurate, execution_date=20220317T000000, start_date=20220318T160049, end_date=20220318T160049
[2022-03-18 21:30:50,019] {local_task_job.py:151} INFO - Task exited with return code 1
