[2022-03-18 00:28:15,072] {taskinstance.py:876} INFO - Dependencies all met for <TaskInstance: user_processing.create_table 2022-03-16T00:00:00+00:00 [queued]>
[2022-03-18 00:28:15,080] {taskinstance.py:876} INFO - Dependencies all met for <TaskInstance: user_processing.create_table 2022-03-16T00:00:00+00:00 [queued]>
[2022-03-18 00:28:15,081] {taskinstance.py:1067} INFO - 
--------------------------------------------------------------------------------
[2022-03-18 00:28:15,081] {taskinstance.py:1068} INFO - Starting attempt 1 of 1
[2022-03-18 00:28:15,081] {taskinstance.py:1069} INFO - 
--------------------------------------------------------------------------------
[2022-03-18 00:28:15,173] {taskinstance.py:1087} INFO - Executing <Task(SqliteOperator): create_table> on 2022-03-16T00:00:00+00:00
[2022-03-18 00:28:15,177] {standard_task_runner.py:52} INFO - Started process 30427 to run task
[2022-03-18 00:28:15,184] {standard_task_runner.py:76} INFO - Running: ['airflow', 'tasks', 'run', 'user_processing', 'create_table', '2022-03-16T00:00:00+00:00', '--job-id', '8', '--pool', 'default_pool', '--raw', '--subdir', 'DAGS_FOLDER/user_processing.py', '--cfg-path', '/tmp/tmp25kcsock', '--error-file', '/tmp/tmp6d6skajr']
[2022-03-18 00:28:15,186] {standard_task_runner.py:77} INFO - Job 8: Subtask create_table
[2022-03-18 00:28:15,299] {logging_mixin.py:104} INFO - Running <TaskInstance: user_processing.create_table 2022-03-16T00:00:00+00:00 [running]> on host pc
[2022-03-18 00:28:15,529] {taskinstance.py:1282} INFO - Exporting the following env vars:
AIRFLOW_CTX_DAG_OWNER=airflow
AIRFLOW_CTX_DAG_ID=user_processing
AIRFLOW_CTX_TASK_ID=create_table
AIRFLOW_CTX_EXECUTION_DATE=2022-03-16T00:00:00+00:00
AIRFLOW_CTX_DAG_RUN_ID=scheduled__2022-03-16T00:00:00+00:00
[2022-03-18 00:28:15,532] {sqlite.py:59} INFO - Executing: 
        create table users(firstname TEXT,lastname TEXT,email TEXT NOT NULL PRIMARY KEY);
    
[2022-03-18 00:28:15,551] {taskinstance.py:1481} ERROR - Task failed with exception
Traceback (most recent call last):
  File "/home/anupam/venv/lib/python3.6/site-packages/airflow/models/taskinstance.py", line 1137, in _run_raw_task
    self._prepare_and_execute_task_with_callbacks(context, task)
  File "/home/anupam/venv/lib/python3.6/site-packages/airflow/models/taskinstance.py", line 1311, in _prepare_and_execute_task_with_callbacks
    result = self._execute_task(context, task_copy)
  File "/home/anupam/venv/lib/python3.6/site-packages/airflow/models/taskinstance.py", line 1341, in _execute_task
    result = task_copy.execute(context=context)
  File "/home/anupam/venv/lib/python3.6/site-packages/airflow/providers/sqlite/operators/sqlite.py", line 61, in execute
    hook.run(self.sql, parameters=self.parameters)
  File "/home/anupam/venv/lib/python3.6/site-packages/airflow/hooks/dbapi.py", line 177, in run
    with closing(self.get_conn()) as conn:
  File "/home/anupam/venv/lib/python3.6/site-packages/airflow/providers/sqlite/hooks/sqlite.py", line 35, in get_conn
    airflow_conn = self.get_connection(conn_id)
  File "/home/anupam/venv/lib/python3.6/site-packages/airflow/hooks/base.py", line 67, in get_connection
    conn = Connection.get_connection_from_secrets(conn_id)
  File "/home/anupam/venv/lib/python3.6/site-packages/airflow/models/connection.py", line 379, in get_connection_from_secrets
    raise AirflowNotFoundException(f"The conn_id `{conn_id}` isn't defined")
airflow.exceptions.AirflowNotFoundException: The conn_id `db_sqlite` isn't defined
[2022-03-18 00:28:15,574] {taskinstance.py:1531} INFO - Marking task as FAILED. dag_id=user_processing, task_id=create_table, execution_date=20220316T000000, start_date=20220317T185815, end_date=20220317T185815
[2022-03-18 00:28:15,718] {local_task_job.py:151} INFO - Task exited with return code 1
