[2022-03-18 21:53:53,070] {taskinstance.py:876} INFO - Dependencies all met for <TaskInstance: trigger_rule.task_1 2022-03-17T00:00:00+00:00 [queued]>
[2022-03-18 21:53:53,103] {taskinstance.py:876} INFO - Dependencies all met for <TaskInstance: trigger_rule.task_1 2022-03-17T00:00:00+00:00 [queued]>
[2022-03-18 21:53:53,103] {taskinstance.py:1067} INFO - 
--------------------------------------------------------------------------------
[2022-03-18 21:53:53,103] {taskinstance.py:1068} INFO - Starting attempt 2 of 2
[2022-03-18 21:53:53,104] {taskinstance.py:1069} INFO - 
--------------------------------------------------------------------------------
[2022-03-18 21:53:53,120] {taskinstance.py:1087} INFO - Executing <Task(BashOperator): task_1> on 2022-03-17T00:00:00+00:00
[2022-03-18 21:53:53,128] {standard_task_runner.py:52} INFO - Started process 13144 to run task
[2022-03-18 21:53:53,136] {standard_task_runner.py:76} INFO - Running: ['airflow', 'tasks', 'run', 'trigger_rule', 'task_1', '2022-03-17T00:00:00+00:00', '--job-id', '71', '--pool', 'default_pool', '--raw', '--subdir', 'DAGS_FOLDER/trigger_rule.py', '--cfg-path', '/tmp/tmpoja_jnb2', '--error-file', '/tmp/tmpm0yc2pbc']
[2022-03-18 21:53:53,140] {standard_task_runner.py:77} INFO - Job 71: Subtask task_1
[2022-03-18 21:53:53,219] {logging_mixin.py:104} INFO - Running <TaskInstance: trigger_rule.task_1 2022-03-17T00:00:00+00:00 [running]> on host pc
[2022-03-18 21:53:53,329] {taskinstance.py:1282} INFO - Exporting the following env vars:
AIRFLOW_CTX_DAG_OWNER=airflow
AIRFLOW_CTX_DAG_ID=trigger_rule
AIRFLOW_CTX_TASK_ID=task_1
AIRFLOW_CTX_EXECUTION_DATE=2022-03-17T00:00:00+00:00
AIRFLOW_CTX_DAG_RUN_ID=scheduled__2022-03-17T00:00:00+00:00
[2022-03-18 21:53:53,330] {subprocess.py:52} INFO - Tmp dir root location: 
 /tmp
[2022-03-18 21:53:53,331] {subprocess.py:63} INFO - Running command: ['bash', '-c', 'exit 1']
[2022-03-18 21:53:53,338] {subprocess.py:75} INFO - Output:
[2022-03-18 21:53:53,340] {subprocess.py:83} INFO - Command exited with return code 1
[2022-03-18 21:53:53,361] {taskinstance.py:1481} ERROR - Task failed with exception
Traceback (most recent call last):
  File "/home/anupam/venv/lib/python3.6/site-packages/airflow/models/taskinstance.py", line 1137, in _run_raw_task
    self._prepare_and_execute_task_with_callbacks(context, task)
  File "/home/anupam/venv/lib/python3.6/site-packages/airflow/models/taskinstance.py", line 1311, in _prepare_and_execute_task_with_callbacks
    result = self._execute_task(context, task_copy)
  File "/home/anupam/venv/lib/python3.6/site-packages/airflow/models/taskinstance.py", line 1341, in _execute_task
    result = task_copy.execute(context=context)
  File "/home/anupam/venv/lib/python3.6/site-packages/airflow/operators/bash.py", line 180, in execute
    raise AirflowException('Bash command failed. The command returned a non-zero exit code.')
airflow.exceptions.AirflowException: Bash command failed. The command returned a non-zero exit code.
[2022-03-18 21:53:53,364] {taskinstance.py:1531} INFO - Marking task as FAILED. dag_id=trigger_rule, task_id=task_1, execution_date=20220317T000000, start_date=20220318T162353, end_date=20220318T162353
[2022-03-18 21:53:53,425] {local_task_job.py:151} INFO - Task exited with return code 1
